Workbook

Sheet from Swathis' report
A3: Count of enrollee_id | B3: Column Labels
A4: Row Labels | B4: Cancelled | C4: Enrolled | D4: Pend | E4: Pend canceled | F4: Pending | G4: Terminated | H4: Grand Total
A5: In Selma's report | B5: 352 | C5: 888 | F5: 10 | G5: 266 | H5: 1516
A6: Not in Selma's report | B6: 115 | C6: 90 | D6: 1 | E6: 5 | F6: 15 | G6: 22 | H6: 248
A7: Grand Total | B7: 467 | C7: 978 | D7: 1 | E7: 5 | F7: 25 | G7: 288 | H7: 1764

Sheet Swathi
A1: coverage_year | B1: GAA_Load_Datetime | C1: household_id | D1: fpl | E1: ssap_application_id | F1: external_application_id | G1: application_type | H1: source | I1: application_status | J1: Insurance_Type | K1: enrollment_id | L1: enrollee_id | M1: M ID in Selma's? | N1: M ID in Selma's report status | O1: person_type | P1: relationship_type | Q1: consumer_category | R1: birth_date | S1: enrollee_first_name | T1: enrollee_last_name | U1: total_indv_responsibility_amt | V1: gross_premium_amt | W1: net_premium_amt | X1: aptc_amt | Y1: csr_amt | Z1: exchange_eligibility_status | AA1: plan_level_combined_bronze | AB1: cms_plan_id | AC1: plan_id | AD1: plan_name | AE1: hios_issuer_id | AF1: insurer_name | AG1: age | AH1: email_address | AI1: phone_number | AJ1: rating_area | AK1: county | AL1: zip | AM1: broker_role | AN1: broker_id | AO1: assister_broker_id | AP1: npn | AQ1: first_name | AR1: last_name | AS1: business_name | AT1: technology_provider | AU1: enrollment_status_description | AV1: enrollee_status_description | AW1: benefit_effective_date | AX1: benefit_end_date | AY1: enrollment_confirmation_date | AZ1: enrollment_create_date | BA1: enrollment_last_update_date | BB1: enrollee_start_date | BC1: enrollee_end_date | BD1: enrollee_create_date | BE1: enrollee_last_update_date | BF1: application_create_date | BG1: application_last_update_date
A2: 2026 | B2: 46204 | C2: 1260196 | D2: 272.23 | E2: 7775808 | F2: NULL | G2: OE | H2: ON | I2: EN | J2: Dental | K2: 212041452 | L2: 1002394459 | M2: =VLOOKUP(L2,Selma!H$1:H$3913,1,FALSE) -> 1002394459 | N2: In Selma's report | O2: Subscriber | P2: Spouse | Q2: New Consumer | R2: 32315 | S2: Kristin | T2: Hahlbohn | U2: 44.77 | V2: 44.77 | W2: 44.77 | X2: 0 | Y2: NULL | Z2: APTC | AA2: HIGH | AB2: 83502GA002000301 | AC2: 3631 | AD2: Best Life Superior Dental Plan | AE2: 83502 | AF2: BEST Life and Health Insurance Company | AG2: 37 | AH2: kahahlbohn@gmail.com | AI2: 4045940517 | AJ2: 3 | AK2: Cobb | AL2: 30064 | AM2: NULL | AN2: NULL | AO2: NULL | AP2: NULL | AQ2: NULL | AR2: NULL | AS2: NULL | AT2: NULL | AU2: Cancelled | AV2: Cancelled | AW2: 46023 | AX2: 46023 | AY2: NULL | AZ2: 46006 | BA2: 46065 | BB2: 46023 | BC2: 46023 | BD2: 46006 | BE2: 46065 | BF2: 46006 | BG2: 46065
A3: 2026 | B3: 46204 | C3: 31838 | D3: NULL | E3: 6865339 | F3: 5178101845 | G3: SEP | H3: ON | I3: EN | J3: Dental | K3: 211037564 | L3: 1000052655 | M3: =VLOOKUP(L3,Selma!H$1:H$3913,1,FALSE) -> 1000052655 | N3: In Selma's report | O3: Subscriber | P3: Spouse | Q3: Active Re-enrollee | R3: 23511 | S3: Rebecca | T3: Safon | U3: 20.37 | V3: 20.37 | W3: 20.37 | X3: NULL | Y3: NULL | Z3: QHP | AA3: LOW | AB3: 83502GA002000801 | AC3: 3634 | AD3: Best Life Essential Basic Dental Plan | AE3: 83502 | AF3: BEST Life and Health Insurance Company | AG3: 61 | AH3: safonscot@gmail.com | AI3: 6784279288 | AJ3: 3 | AK3: FULTON | AL3: 30312 | AM3: AGENT | AN3: 1312636 | AO3: 1312636 | AP3: 21576872 | AQ3: Muhammad | AR3: Naseem | AS3: NULL | AT3: NULL | AU3: Enrolled | AV3: Enrolled | AW3: 46023 | AX3: 46387 | AY3: 45946 | AZ3: 45946 | BA3: 45966 | BB3: 46023 | BC3: 46387 | BD3: 45946 | BE3: 45966 | BF3: 45966 | BG3: 46002
A4: 2026 | B4: 46204 | C4: 309257 | D4: NULL | E4: 6015636 | F4: 5150702036 | G4: OE | H4: CN | I4: EN | J4: Dental | K4: 211183913 | L4: 1000512462 | M4: =VLOOKUP(L4,Selma!H$1:H$3913,1,FALSE) -> #N/A | N4: Not in Selma's report | O4: Enrollee | P4: Child | Q4: Automatic Re-enrollee | R4: 36800 | S4: Peter | T4: Yoon | U4: 41.9 | V4: 215.24 | W4: 215.24 | X4: NULL | Y4: NULL | Z4: QHP | AA4: HIGH | AB4: 83502GA002000301 | AC4: 3631 | AD4: Best Life Superior Dental Plan | AE4: 83502 | AF4: BEST Life and Health Insurance Company | AG4: 25 | AH4: jackwyoon@gmail.com | AI4: 6783371048 | AJ4: 3 | AK4: Gwinnett | AL4: 30518 | AM4: AGENT | AN4: 10293 | AO4: 10293 | AP4: 18436232 | AQ4: ELLICE | AR4: LEE | AS4: HealthSherpa | AT4: HealthSherpa | AU4: Enrolled | AV4: Enrolled | AW4: 46023 | AX4: 46387 | AY4: 45946 | AZ4: 45946 | BA4: 46059 | BB4: 46023 | BC4: 46387 | BD4: 45946 | BE4: 46059 | BF4: 45934 | BG4: 46008
A5: 2026 | B5: 46204 | C5: 309257 | D5: NULL | E5: 6015636 | F5: 5150702036 | G5: OE | H5: CN | I5: EN | J5: Dental | K5: 211183913 | L5: 1000512461 | M5: =VLOOKUP(L5,Selma!H$1:H$3913,1,FALSE) -> #N/A | N5: Not in Selma's report | O5: Enrollee | P5: Child | Q5: Automatic Re-enrollee | R5: 37887 | S5: Jennifer | T5: Yoon | U5: 41.9 | V5: 215.24 | W5: 215.24 | X5: NULL | Y5: NULL | Z5: QHP | AA5: HIGH | AB5: 83502GA002000301 | AC5: 3631 | AD5: Best Life Superior Dental Plan | AE5: 83502 | AF5: BEST Life and Health Insurance Company | AG5: 22 | AH5: jackwyoon@gmail.com | AI5: 6783371048 | AJ5: 3 | AK5: Gwinnett | AL5: 30518 | AM5: AGENT | AN5: 10293 | AO5: 10293 | AP5: 18436232 | AQ5: ELLICE | AR5: LEE | AS5: HealthSherpa | AT5: HealthSherpa | AU5: Enrolled | AV5: Enrolled | AW5: 46023 | AX5: 46387 | AY5: 45946 | AZ5: 45946 | BA5: 46059 | BB5: 46023 | BC5: 46387 | BD5: 45946 | BE5: 46059 | BF5: 45934 | BG5: 46008
A6: 2026 | B6: 46204 | C6: 309257 | D6: NULL | E6: 6015636 | F6: 5150702036 | G6: OE | H6: CN | I6: EN | J6: Dental | K6: 211183913 | L6: 1000512464 | M6: =VLOOKUP(L6,Selma!H$1:H$3913,1,FALSE) -> #N/A | N6: Not in Selma's report | O6: Enrollee | P6: Child | Q6: Automatic Re-enrollee | R6: 38533 | S6: Brian | T6: Yoon | U6: 41.9 | V6: 215.24 | W6: 215.24 | X6: NULL | Y6: NULL | Z6: QHP | AA6: HIGH | AB6: 83502GA002000301 | AC6: 3631 | AD6: Best Life Superior Dental Plan | AE6: 83502 | AF6: BEST Life and Health Insurance Company | AG6: 20 | AH6: jackwyoon@gmail.com | AI6: 6783371048 | AJ6: 3 | AK6: Gwinnett | AL6: 30518 | AM6: AGENT | AN6: 10293 | AO6: 10293 | AP6: 18436232 | AQ6: ELLICE | AR6: LEE | AS6: HealthSherpa | AT6: HealthSherpa | AU6: Enrolled | AV6: Enrolled | AW6: 46023 | AX6: 46387 | AY6: 45946 | AZ6: 45946 | BA6: 46059 | BB6: 46023 | BC6: 46387 | BD6: 45946 | BE6: 46059 | BF6: 45934 | BG6: 46008
A7: 2026 | B7: 46204 | C7: 309257 | D7: NULL | E7: 6015636 | F7: 5150702036 | G7: OE | H7: CN | I7: EN | J7: Dental | K7: 211183913 | L7: 1000512463 | M7: =VLOOKUP(L7,Selma!H$1:H$3913,1,FALSE) -> #N/A | N7: Not in Selma's report | O7: Enrollee | P7: Spouse | Q7: Automatic Re-enrollee | R7: 27129 | S7: Annie | T7: Jung | U7: 44.77 | V7: 215.24 | W7: 215.24 | X7: NULL | Y7: NULL | Z7: QHP | AA7: HIGH | AB7: 83502GA002000301 | AC7: 3631 | AD7: Best Life Superior Dental Plan | AE7: 83502 | AF7: BEST Life and Health Insurance Company | AG7: 51 | AH7: jackwyoon@gmail.com | AI7: 6783371048 | AJ7: 3 | AK7: Gwinnett | AL7: 30518 | AM7: AGENT | AN7: 10293 | AO7: 10293 | AP7: 18436232 | AQ7: ELLICE | AR7: LEE | AS7: HealthSherpa | AT7: HealthSherpa | AU7: Enrolled | AV7: Enrolled | AW7: 46023 | AX7: 46387 | AY7: 45946 | AZ7: 45946 | BA7: 46059 | BB7: 46023 | BC7: 46387 | BD7: 45946 | BE7: 46059 | BF7: 45934 | BG7: 46008
A8: 2026 | B8: 46204 | C8: 309257 | D8: NULL | E8: 6015636 | F8: 5150702036 | G8: OE | H8: CN | I8: EN | J8: Dental | K8: 211183913 | L8: 1000512465 | M8: =VLOOKUP(L8,Selma!H$1:H$3913,1,FALSE) -> #N/A | N8: Not in Selma's report | O8: Subscriber | P8: Self | Q8: Automatic Re-enrollee | R8: 24880 | S8: Jack | T8: Yoon | U8: 44.77 | V8: 215.24 | W8: 215.24 | X8: NULL | Y8: NULL | Z8: QHP | AA8: HIGH | AB8: 83502GA002000301 | AC8: 3631 | AD8: Best Life Superior Dental Plan | AE8: 83502 | AF8: BEST Life and Health Insurance Company | AG8: 57 | AH8: jackwyoon@gmail.com | AI8: 6783371048 | AJ8: 3 | AK8: Gwinnett | AL8: 30518 | AM8: AGENT | AN8: 10293 | AO8: 10293 | AP8: 18436232 | AQ8: ELLICE | AR8: LEE | AS8: HealthSherpa | AT8: HealthSherpa | AU8: Enrolled | AV8: Enrolled | AW8: 46023 | AX8: 46387 | AY8: 45946 | AZ8: 45946 | BA8: 46059 | BB8: 46023 | BC8: 46387 | BD8: 45946 | BE8: 46059 | BF8: 45934 | BG8: 46008
A9: 2026 | B9: 46204 | C9: 381682 | D9: 0 | E9: 5791787 | F9: 5412252607 | G9: OE | H9: CN | I9: EN | J9: Dental | K9: 211537282 | L9: 1000631776 | M9: =VLOOKUP(L9,Selma!H$1:H$3913,1,FALSE) -> 1000631776 | N9: In Selma's report | O9: Subscriber | P9: Self | Q9: Active Re-enrollee | R9: 35843 | S9: Charles | T9: Franklin | U9: 36.67 | V9: 36.67 | W9: 36.67 | X9: NULL | Y9: NULL | Z9: QHP | AA9: HIGH | AB9: 83502GA002000701 | AC9: 3633 | AD9: Best Life Preferred Dental Plan | AE9: 83502 | AF9: BEST Life and Health Insurance Company | AG9: 27 | AH9: colefranklin217@yahoo.com | AI9: 4044529086 | AJ9: 3 | AK9: COBB | AL9: 30101 | AM9: AGENT | AN9: 551626 | AO9: 551626 | AP9: 1262563 | AQ9: JOSEPH JOHN | AR9: CHVATAL | AS9: NULL | AT9: NULL | AU9: Enrolled | AV9: Enrolled | AW9: 46023 | AX9: 46387 | AY9: 45947 | AZ9: 45947 | BA9: 45947 | BB9: 46023 | BC9: 46387 | BD9: 45947 | BE9: 45947 | BF9: 45934 | BG9: 46013
A10: 2026 | B10: 46204 | C10: 383743 | D10: NULL | E10: 8246472 | F10: 5153844815 | G10: SEP | H10: ON | I10: EN | J10: Dental | K10: 211051916 | L10: 1000635444 | M10: =VLOOKUP(L10,Selma!H$1:H$3913,1,FALSE) -> 1000635444 | N10: In Selma's report | O10: Subscriber | P10: Spouse | Q10: Automatic Re-enrollee | R10: 23795 | S10: Beverly | T10: Holman | U10: 22.01 | V10: 22.01 | W10: 22.01 | X10: NULL | Y10: NULL | Z10: QHP | AA10: LOW | AB10: 83502GA002000601 | AC10: 3632 | AD10: Best Life Essential Value Dental Plan | AE10: 83502 | AF10: BEST Life and Health Insurance Company | AG10: 60 | AH10: bholman124@yahoo.com | AI10: 5107145154 | AJ10: 10 | AK10: HALL | AL10: 30542 | AM10: AGENT | AN10: 548527 | AO10: 548527 | AP10: 9126142 | AQ10: BRENDA J | AR10: GONZALEZ | AS10: NULL | AT10: NULL | AU10: Enrolled | AV10: Enrolled | AW10: 46023 | AX10: 46387 | AY10: 45946 | AZ10: 45946 | BA10: 46042 | BB10: 46023 | BC10: 46387 | BD10: 45946 | BE10: 46042 | BF10: 46042 | BG10: 46042
A11: 2026 | B11: 46204 | C11: 581489 | D11: NULL | E11: 8976698 | F11: 5154574740 | G11: SEP | H11: RR | I11: EN | J11: Dental | K11: 1000128793 | L11: 1000963464 | M11: =VLOOKUP(L11,Selma!H$1:H$3913,1,FALSE) -> #N/A | N11: Not in Selma's report | O11: Subscriber | P11: Self | Q11: Active Re-enrollee | R11: 31308 | S11: Anthony | T11: Smith | U11: 44.77 | V11: 44.77 | W11: 44.77 | X11: NULL | Y11: NULL | Z11: QHP | AA11: HIGH | AB11: 83502GA002000301 | AC11: 3631 | AD11: Best Life Superior Dental Plan | AE11: 83502 | AF11: BEST Life and Health Insurance Company | AG11: 40 | AH11: djlilant119@gmail.com | AI11: 4047801362 | AJ11: 3 | AK11: Henry | AL11: 30253 | AM11: AGENT | AN11: 873610 | AO11: 873610 | AP11: 21343326 | AQ11: Yessenya | AR11: Sanchez Hernandez | AS11: HealthSherpa | AT11: HealthSherpa | AU11: Cancelled | AV11: Cancelled | AW11: 46113 | AX11: 46113 | AY11: NULL | AZ11: 46106 | BA11: 46130 | BB11: 46113 | BC11: 46113 | BD11: 46106 | BE11: 46129 | BF11: 46130 | BG11: 46130
A12: 2026 | B12: 46204 | C12: 650866 | D12: NULL | E12: 7677354 | F12: 5137647580 | G12: OE | H12: EDE | I12: EN | J12: Dental | K12: 211308422 | L12: 1001078511 | M12: =VLOOKUP(L12,Selma!H$1:H$3913,1,FALSE) -> 1001078511 | N12: In Selma's report | O12: Subscriber | P12: Self | Q12: Active Re-enrollee | R12: 25327 | S12: Melinda | T12: Beatenbough | U12: 44.77 | V12: 131.44 | W12: 131.44 | X12: NULL | Y12: NULL | Z12: QHP | AA12: HIGH | AB12: 83502GA002000301 | AC12: 3631 | AD12: Best Life Superior Dental Plan | AE12: 83502 | AF12: BEST Life and Health Insurance Company | AG12: 56 | AH12: mindi.beat@gmail.com | AI12: 4047879642 | AJ12: 3 | AK12: Clayton | AL12: 30236 | AM12: AGENT | AN12: 548378 | AO12: 548378 | AP12: 19816672 | AQ12: BENIA | AR12: RENE | AS12: Centene-Ambetter | AT12: HealthSherpa | AU12: Cancelled | AV12: Cancelled | AW12: 46023 | AX12: 46023 | AY12: 45947 | AZ12: 45947 | BA12: 46003 | BB12: 46023 | BC12: 46023 | BD12: 45947 | BE12: 46003 | BF12: 46003 | BG12: 46003
A13: 2026 | B13: 46204 | C13: 683835 | D13: NULL | E13: 7491604 | F13: 5128928188 | G13: SEP | H13: ON | I13: EN | J13: Dental | K13: 212106737 | L13: 1001133291 | M13: =VLOOKUP(L13,Selma!H$1:H$3913,1,FALSE) -> 1001133291 | N13: In Selma's report | O13: Subscriber | P13: Self | Q13: Active Re-enrollee | R13: 27263 | S13: AZIZ | T13: DAMANI | U13: 44.77 | V13: 131.44 | W13: 131.44 | X13: NULL | Y13: NULL | Z13: QHP | AA13: HIGH | AB13: 83502GA002000301 | AC13: 3631 | AD13: Best Life Superior Dental Plan | AE13: 83502 | AF13: BEST Life and Health Insurance Company | AG13: 51 | AH13: aziz@damaniholdings.com | AI13: 4047757986 | AJ13: 3 | AK13: GWINNETT | AL13: 30097 | AM13: AGENT | AN13: 552558 | AO13: 552558 | AP13: 8184400 | AQ13: MELISSA J | AR13: COCHRAN | AS13: NULL | AT13: NULL | AU13: Terminated | AV13: Terminated | AW13: 46023 | AX13: 46081 | AY13: 46031 | AZ13: 46015 | BA13: 46124 | BB13: 46023 | BC13: 46081 | BD13: 46015 | BE13: 46124 | BF13: 45994 | BG13: 46015
A14: 2026 | B14: 46204 | C14: 683835 | D14: NULL | E14: 7491604 | F14: 5128928188 | G14: SEP | H14: ON | I14: EN | J14: Dental | K14: 212106737 | L14: 1001133292 | M14: =VLOOKUP(L14,Selma!H$1:H$3913,1,FALSE) -> 1001133292 | N14: In Selma's report | O14: Enrollee | P14: Spouse | Q14: Active Re-enrollee | R14: 28038 | S14: SONIA | T14: DAMANI | U14: 44.77 | V14: 131.44 | W14: 131.44 | X14: NULL | Y14: NULL | Z14: QHP | AA14: HIGH | AB14: 83502GA002000301 | AC14: 3631 | AD14: Best Life Superior Dental Plan | AE14: 83502 | AF14: BEST Life and Health Insurance Company | AG14: 49 | AH14: aziz@damaniholdings.com | AI14: 4047757986 | AJ14: 3 | AK14: GWINNETT | AL14: 30097 | AM14: AGENT | AN14: 552558 | AO14: 552558 | AP14: 8184400 | AQ14: MELISSA J | AR14: COCHRAN | AS14: NULL | AT14: NULL | AU14: Terminated | AV14: Terminated | AW14: 46023 | AX14: 46081 | AY14: 46031 | AZ14: 46015 | BA14: 46124 | BB14: 46023 | BC14: 46081 | BD14: 46015 | BE14: 46124 | BF14: 45994 | BG14: 46015
A15: 2026 | B15: 46204 | C15: 683835 | D15: NULL | E15: 7491604 | F15: 5128928188 | G15: SEP | H15: ON | I15: EN | J15: Dental | K15: 212106737 | L15: 1001133293 | M15: =VLOOKUP(L15,Selma!H$1:H$3913,1,FALSE) -> 1001133293 | N15: In Selma's report | O15: Enrollee | P15: Child | Q15: Active Re-enrollee | R15: 38554 | S15: AMAR | T15: DAMANI | U15: 41.9 | V15: 131.44 | W15: 131.44 | X15: NULL | Y15: NULL | Z15: QHP | AA15: HIGH | AB15: 83502GA002000301 | AC15: 3631 | AD15: Best Life Superior Dental Plan | AE15: 83502 | AF15: BEST Life and Health Insurance Company | AG15: 20 | AH15: aziz@damaniholdings.com | AI15: 4047757986 | AJ15: 3 | AK15: GWINNETT | AL15: 30097 | AM15: AGENT | AN15: 552558 | AO15: 552558 | AP15: 8184400 | AQ15: MELISSA J | AR15: COCHRAN | AS15: NULL | AT15: NULL | AU15: Terminated | AV15: Terminated | AW15: 46023 | AX15: 46081 | AY15: 46031 | AZ15: 46015 | BA15: 46124 | BB15: 46023 | BC15: 46081 | BD15: 46015 | BE15: 46124 | BF15: 45994 | BG15: 46015
A16: 2026 | B16: 46204 | C16: 693469 | D16: 0 | E16: 8275604 | F16: GAT123003925 | G16: SEP | H16: ON | I16: PN | J16: Dental | K16: 212260531 | L16: 1001148905 | M16: =VLOOKUP(L16,Selma!H$1:H$3913,1,FALSE) -> #N/A | N16: Not in Selma's report | O16: Subscriber | P16: Self | Q16: Active Re-enrollee | R16: 34851 | S16: TABITHA | T16: SMITH | U16: 17.17 | V16: 17.17 | W16: 17.17 | X16: NULL | Y16: NULL | Z16: QHP | AA16: LOW | AB16: 83502GA002000801 | AC16: 3634 | AD16: Best Life Essential Basic Dental Plan | AE16: 83502 | AF16: BEST Life and Health Insurance Company | AG16: 30 | AH16: lilbitbit7970@gmail.com | AI16: 4782835787 | AJ16: 12 | AK16: Bibb | AL16: 31206 | AM16: AGENT | AN16: 9371 | AO16: 9371 | AP16: 20546556 | AQ16: RENE | AR16: NARANJO | AS16: HealthSherpa | AT16: HealthSherpa | AU16: Cancelled | AV16: Cancelled | AW16: 46054 | AX16: 46054 | AY16: NULL | AZ16: 46046 | BA16: 46046 | BB16: 46054 | BC16: 46054 | BD16: 46046 | BE16: 46046 | BF16: 46045 | BG16: 46046
A17: 2026 | B17: 46204 | C17: 756034 | D17: NULL | E17: 7098384 | F17: 5171948999 | G17: SEP | H17: ON | I17: EN | J17: Dental | K17: 210574895 | L17: 1001252609 | M17: =VLOOKUP(L17,Selma!H$1:H$3913,1,FALSE) -> 1001252609 | N17: In Selma's report | O17: Subscriber | P17: Self | Q17: Active Re-enrollee | R17: 26942 | S17: Charles | T17: Franklin | U17: 36.67 | V17: 36.67 | W17: 36.67 | X17: NULL | Y17: NULL | Z17: QHP | AA17: HIGH | AB17: 83502GA002000701 | AC17: 3633 | AD17: Best Life Preferred Dental Plan | AE17: 83502 | AF17: BEST Life and Health Insurance Company | AG17: 52 | AH17: franklinc37@yahoo.com | AI17: 7706161697 | AJ17: 3 | AK17: COBB | AL17: 30101 | AM17: AGENT | AN17: 551626 | AO17: 551626 | AP17: 1262563 | AQ17: JOSEPH JOHN | AR17: CHVATAL | AS17: NULL | AT17: NULL | AU17: Terminated | AV17: Terminated | AW17: 46023 | AX17: 46203 | AY17: 45946 | AZ17: 45946 | BA17: 46188 | BB17: 46023 | BC17: 46203 | BD17: 45946 | BE17: 46188 | BF17: 45981 | BG17: 46009
A18: 2026 | B18: 46204 | C18: 890265 | D18: 0 | E18: 8425250 | F18: 5168583477 | G18: SEP | H18: ON | I18: PN | J18: Dental | K18: 1000118019 | L18: 1001475165 | M18: =VLOOKUP(L18,Selma!H$1:H$3913,1,FALSE) -> #N/A | N18: Not in Selma's report | O18: Subscriber | P18: Self | Q18: Automatic Re-enrollee | R18: 25892 | S18: Catherine | T18: Archer | U18: 44.77 | V18: 44.77 | W18: 44.77 | X18: NULL | Y18: NULL | Z18: QHP | AA18: HIGH | AB18: 83502GA002000301 | AC18: 3631 | AD18: Best Life Superior Dental Plan | AE18: 83502 | AF18: BEST Life and Health Insurance Company | AG18: 55 | AH18: catarcher3@yahoo.com | AI18: 4706302442 | AJ18: 3 | AK18: Bartow | AL18: 30120 | AM18: AGENT | AN18: 720 | AO18: 720 | AP18: 18205745 | AQ18: PAOLA | AR18: FRITZ | AS18: HealthSherpa | AT18: HealthSherpa | AU18: Cancelled | AV18: Cancelled | AW18: 46113 | AX18: 46113 | AY18: NULL | AZ18: 46101 | BA18: 46104 | BB18: 46113 | BC18: 46113 | BD18: 46101 | BE18: 46104 | BF18: 46061 | BG18: 46141
A19: 2026 | B19: 46204 | C19: 937417 | D19: NULL | E19: 5928881 | F19: 5175937903 | G19: OE | H19: CN | I19: EN | J19: Dental | K19: 211519809 | L19: 1001553377 | M19: =VLOOKUP(L19,Selma!H$1:H$3913,1,FALSE) -> 1001553377 | N19: In Selma's report | O19: Enrollee | P19: Spouse | Q19: Automatic Re-enrollee | R19: 28089 | S19: Donna | T19: Johnson | U19: 38.23 | V19: 76.46 | W19: 76.46 | X19: NULL | Y19: NULL | Z19: QHP | AA19: HIGH | AB19: 83502GA002000301 | AC19: 3631 | AD19: Best Life Superior Dental Plan | AE19: 83502 | AF19: BEST Life and Health Insurance Company | AG19: 49 | AH19: jwms.andy@gmail.com | AI19: 9122222210 | AJ19: 6 | AK19: GLYNN | AL19: 31523 | AM19: AGENT | AN19: 4854 | AO19: 4854 | AP19: 17410092 | AQ19: TRICE | AR19: THORNTON | AS19: NULL | AT19: NULL | AU19: Enrolled | AV19: Enrolled | AW19: 46023 | AX19: 46387 | AY19: 45947 | AZ19: 45947 | BA19: 45947 | BB19: 46023 | BC19: 46387 | BD19: 45947 | BE19: 45947 | BF19: 45934 | BG19: 45947
A20: 2026 | B20: 46204 | C20: 937417 | D20: NULL | E20: 5928881 | F20: 5175937903 | G20: OE | H20: CN | I20: EN | J20: Dental | K20: 211519809 | L20: 1001553376 | M20: =VLOOKUP(L20,Selma!H$1:H$3913,1,FALSE) -> 1001553376 | N20: In Selma's report | O20: Subscriber | P20: Self | Q20: Automatic Re-enrollee | R20: 26841 | S20: Andrew | T20: Johnson | U20: 38.23 | V20: 76.46 | W20: 76.46 | X20: NULL | Y20: NULL | Z20: QHP | AA20: HIGH | AB20: 83502GA002000301 | AC20: 3631 | AD20: Best Life Superior Dental Plan | AE20: 83502 | AF20: BEST Life and Health Insurance Company | AG20: 52 | AH20: jwms.andy@gmail.com | AI20: 9122222210 | AJ20: 6 | AK20: GLYNN | AL20: 31523 | AM20: AGENT | AN20: 4854 | AO20: 4854 | AP20: 17410092 | AQ20: TRICE | AR20: THORNTON | AS20: NULL | AT20: NULL | AU20: Enrolled | AV20: Enrolled | AW20: 46023 | AX20: 46387 | AY20: 45947 | AZ20: 45947 | BA20: 45947 | BB20: 46023 | BC20: 46387 | BD20: 45947 | BE20: 45947 | BF20: 45934 | BG20: 45947
A21: 2026 | B21: 46204 | C21: 1013137 | D21: NULL | E21: 6990522 | F21: 5236386575 | G21: OE | H21: EDE | I21: EN | J21: Dental | K21: 210983425 | L21: 1001679105 | M21: =VLOOKUP(L21,Selma!H$1:H$3913,1,FALSE) -> 1001679105 | N21: In Selma's report | O21: Subscriber | P21: Self | Q21: Active Re-enrollee | R21: 31875 | S21: Richard | T21: Holtzman | U21: 20.37 | V21: 20.37 | W21: 20.37 | X21: NULL | Y21: NULL | Z21: QHP | AA21: LOW | AB21: 83502GA002000801 | AC21: 3634 | AD21: Best Life Essential Basic Dental Plan | AE21: 83502 | AF21: BEST Life and Health Insurance Company | AG21: 38 | AH21: richieholtzman@gmail.com | AI21: 7703773818 | AJ21: 3 | AK21: Fulton | AL21: 30075 | AM21: AGENT | AN21: 4466 | AO21: 4466 | AP21: 20389330 | AQ21: JOEL | AR21: FULGHUM | AS21: HealthSherpa | AT21: HealthSherpa | AU21: Enrolled | AV21: Enrolled | AW21: 46023 | AX21: 46387 | AY21: 45946 | AZ21: 45946 | BA21: 45974 | BB21: 46023 | BC21: 46387 | BD21: 45946 | BE21: 45974 | BF21: 45974 | BG21: 45974
A22: 2026 | B22: 46204 | C22: 1060766 | D22: 0 | E22: 8680945 | F22: NULL | G22: SEP | H22: RR | I22: EN | J22: Dental | K22: 212185644 | L22: 1001796137 | M22: =VLOOKUP(L22,Selma!H$1:H$3913,1,FALSE) -> 1001796137 | N22: In Selma's report | O22: Subscriber | P22: Self | Q22: Automatic Re-enrollee | R22: 36684 | S22: Mary | T22: Austin | U22: 29.32 | V22: 29.32 | W22: 29.32 | X22: NULL | Y22: NULL | Z22: QHP | AA22: HIGH | AB22: 83502GA002000701 | AC22: 3633 | AD22: Best Life Preferred Dental Plan | AE22: 83502 | AF22: BEST Life and Health Insurance Company | AG22: 25 | AH22: marymac060700@gmail.com | AI22: 7064363928 | AJ22: 10 | AK22: Hart | AL22: 30643 | AM22: AGENT | AN22: 5773 | AO22: 5773 | AP22: 20567974 | AQ22: STEPHEN | AR22: SMITH | AS22: HealthSherpa | AT22: HealthSherpa | AU22: Cancelled | AV22: Cancelled | AW22: 46054 | AX22: 46054 | AY22: NULL | AZ22: 46032 | BA22: 46094 | BB22: 46054 | BC22: 46054 | BD22: 46032 | BE22: 46094 | BF22: 46087 | BG22: 46094
A23: 2026 | B23: 46204 | C23: 2376401 | D23: NULL | E23: 9349217 | F23: NULL | G23: SEP | H23: ON | I23: EN | J23: Dental | K23: 1000028484 | L23: 1007152241 | M23: =VLOOKUP(L23,Selma!H$1:H$3913,1,FALSE) -> 1007152241 | N23: In Selma's report | O23: Subscriber | P23: Self | Q23: New Consumer | R23: 35870 | S23: Ailisha | T23: Casey | U23: 36.67 | V23: 36.67 | W23: 36.67 | X23: NULL | Y23: NULL | Z23: QHP | AA23: HIGH | AB23: 83502GA002000701 | AC23: 3633 | AD23: Best Life Preferred Dental Plan | AE23: 83502 | AF23: BEST Life and Health Insurance Company | AG23: 27 | AH23: ailishacasey@yahoo.com | AI23: 6786547693 | AJ23: 3 | AK23: Fulton | AL23: 30305 | AM23: AGENT | AN23: 554729 | AO23: 554729 | AP23: 1316142 | AQ23: EDWARD WITTWER | AR23: OFFICER | AS23: NULL | AT23: NULL | AU23: Terminated | AV23: Terminated | AW23: 46082 | AX23: 46142 | AY23: 46106 | AZ23: 46065 | BA23: 46189 | BB23: 46082 | BC23: 46142 | BD23: 46065 | BE23: 46189 | BF23: 46189 | BG23: 46189
A24: 2026 | B24: 46204 | C24: 193864 | D24: 118.2 | E24: 5747101 | F24: 5422104947 | G24: OE | H24: CN | I24: EN | J24: Dental | K24: 212238524 | L24: 1000320577 | M24: =VLOOKUP(L24,Selma!H$1:H$3913,1,FALSE) -> #N/A | N24: Not in Selma's report | O24: Enrollee | P24: Child | Q24: Automatic Re-enrollee | R24: 43779 | S24: Caroline | T24: Nelson | U24: 28.77 | V24: 51.68 | W24: 51.68 | X24: NULL | Y24: NULL | Z24: APTC_CSR | AA24: LOW | AB24: 83502GA002000601 | AC24: 3632 | AD24: Best Life Essential Value Dental Plan | AE24: 83502 | AF24: BEST Life and Health Insurance Company | AG24: 6 | AH24: jacob291989@gmail.com | AI24: 7063020878 | AJ24: 8 | AK24: Troup | AL24: 30241 | AM24: AGENT | AN24: 2728 | AO24: 2728 | AP24: 17178212 | AQ24: LADALE | AR24: LANE | AS24: HealthSherpa | AT24: HealthSherpa | AU24: Cancelled | AV24: Cancelled | AW24: 46054 | AX24: 46054 | AY24: NULL | AZ24: 46037 | BA24: 46094 | BB24: 46054 | BC24: 46054 | BD24: 46037 | BE24: 46094 | BF24: 45934 | BG24: 46094
A25: 2026 | B25: 46204 | C25: 229605 | D25: 100.05 | E25: 7833010 | F25: 5145476766 | G25: OE | H25: ON | I25: EN | J25: Dental | K25: 212223856 | L25: 1000380036 | M25: =VLOOKUP(L25,Selma!H$1:H$3913,1,FALSE) -> #N/A | N25: Not in Selma's report | O25: Enrollee | P25: Child | Q25: New Consumer | R25: 38125 | S25: Cameron | T25: Pitts | U25: 35.79 | V25: 74.02 | W25: 74.02 | X25: NULL | Y25: NULL | Z25: APTC_CSR | AA25: HIGH | AB25: 83502GA002000301 | AC25: 3631 | AD25: Best Life Superior Dental Plan | AE25: 83502 | AF25: BEST Life and Health Insurance Company | AG25: 21 | AH25: pittsmobiletire@gmail.com | AI25: 2292568961 | AJ25: 1 | AK25: Sumter | AL25: 31709 | AM25: AGENT | AN25: 1736 | AO25: 1736 | AP25: 4649559 | AQ25: ANGELA | AR25: BOVELL | AS25: HealthSherpa | AT25: HealthSherpa | AU25: Cancelled | AV25: Cancelled | AW25: 46054 | AX25: 46054 | AY25: NULL | AZ25: 46037 | BA25: 46037 | BB25: 46054 | BC25: 46054 | BD25: 46037 | BE25: 46037 | BF25: 46008 | BG25: 46191
A26: 2026 | B26: 46204 | C26: 323288 | D26: 102.77 | E26: 9313815 | F26: GAT50175098 | G26: QEP | H26: EDE | I26: EN | J26: Dental | K26: 212061197 | L26: 1000534867 | M26: =VLOOKUP(L26,Selma!H$1:H$3913,1,FALSE) -> #N/A | N26: Not in Selma's report | O26: Enrollee | P26: Spouse | Q26: Active Re-enrollee | R26: 26813 | S26: Melinda | T26: Muhammad | U26: 38.98 | V26: 77.96 | W26: 77.96 | X26: NULL | Y26: NULL | Z26: APTC_CSR | AA26: HIGH | AB26: 83502GA002000301 | AC26: 3631 | AD26: Best Life Superior Dental Plan | AE26: 83502 | AF26: BEST Life and Health Insurance Company | AG26: 52 | AH26: mshaymuhammad1@gmail.com | AI26: 7064240656 | AJ26: 2 | AK26: Oglethorpe | AL26: 30669 | AM26: AGENT | AN26: 3568 | AO26: 3568 | AP26: 17366906 | AQ26: LUIS | AR26: DE LA ROSA | AS26: HealthSherpa | AT26: HealthSherpa | AU26: Cancelled | AV26: Cancelled | AW26: 46023 | AX26: 46023 | AY26: NULL | AZ26: 46006 | BA26: 46065 | BB26: 46023 | BC26: 46023 | BD26: 46006 | BE26: 46065 | BF26: 46182 | BG26: 46185
A27: 2026 | B27: 46204 | C27: 328969 | D27: 120.38 | E27: 9291722 | F27: 5167824520 | G27: SEP | H27: ON | I27: EN | J27: Dental | K27: 212034099 | L27: 1000544826 | M27: =VLOOKUP(L27,Selma!H$1:H$3913,1,FALSE) -> #N/A | N27: Not in Selma's report | O27: Enrollee | P27: Spouse | Q27: Active Re-enrollee | R27: 26415 | S27: Gerald | T27: Wesley | U27: 39.79 | V27: 79.58 | W27: 79.58 | X27: 0 | Y27: NULL | Z27: APTC_CSR | AA27: HIGH | AB27: 83502GA002000301 | AC27: 3631 | AD27: Best Life Superior Dental Plan | AE27: 83502 | AF27: BEST Life and Health Insurance Company | AG27: 53 | AH27: shanika314wesley@gmail.com | AI27: 7708758935 | AJ27: 8 | AK27: Troup | AL27: 30241 | AM27: AGENT | AN27: 8484 | AO27: 8484 | AP27: 19237196 | AQ27: NANA | AR27: NASH | AS27: HealthSherpa | AT27: HealthSherpa | AU27: Cancelled | AV27: Cancelled | AW27: 46023 | AX27: 46023 | AY27: NULL | AZ27: 46006 | BA27: 46065 | BB27: 46023 | BC27: 46023 | BD27: 46006 | BE27: 46065 | BF27: 46177 | BG27: 46177
A28: 2026 | B28: 46204 | C28: 376722 | D28: 108.82 | E28: 5635057 | F28: 5308338546 | G28: OE | H28: CN | I28: EN | J28: Dental | K28: 210659907 | L28: 1000623919 | M28: =VLOOKUP(L28,Selma!H$1:H$3913,1,FALSE) -> 1000623919 | N28: In Selma's report | O28: Enrollee | P28: Self | Q28: Active Re-enrollee | R28: 22475 | S28: Mosun | T28: Adekunle | U28: 53.72 | V28: 98.49 | W28: 98.49 | X28: NULL | Y28: NULL | Z28: APTC_CSR | AA28: HIGH | AB28: 83502GA002000301 | AC28: 3631 | AD28: Best Life Superior Dental Plan | AE28: 83502 | AF28: BEST Life and Health Insurance Company | AG28: 64 | AH28: hkmcare@pm.me | AI28: 7707224819 | AJ28: 3 | AK28: ROCKDALE | AL28: 30094 | AM28: AGENT | AN28: 548527 | AO28: 548527 | AP28: 9126142 | AQ28: BRENDA J | AR28: GONZALEZ | AS28: NULL | AT28: NULL | AU28: Cancelled | AV28: Cancelled | AW28: 46023 | AX28: 46023 | AY28: 45946 | AZ28: 45946 | BA28: 46061 | BB28: 46023 | BC28: 46023 | BD28: 45946 | BE28: 46061 | BF28: 45934 | BG28: 46061
A29: 2026 | B29: 46204 | C29: 398575 | D29: 120.57 | E29: 5801548 | F29: 5131894152 | G29: OE | H29: CN | I29: EN | J29: Dental | K29: 210631260 | L29: 1000659779 | M29: =VLOOKUP(L29,Selma!H$1:H$3913,1,FALSE) -> 1000659779 | N29: In Selma's report | O29: Enrollee | P29: Spouse | Q29: Automatic Re-enrollee | R29: 28716 | S29: Uriel | T29: Rubio Ponce | U29: 16.72 | V29: 33.44 | W29: 33.44 | X29: NULL | Y29: NULL | Z29: APTC_CSR | AA29: LOW | AB29: 83502GA002000801 | AC29: 3634 | AD29: Best Life Essential Basic Dental Plan | AE29: 83502 | AF29: BEST Life and Health Insurance Company | AG29: 47 | AH29: evelia1977@icloud.com | AI29: 7069805280 | AJ29: 9 | AK29: WHITFIELD | AL29: 30720 | AM29: AGENT | AN29: 1760344 | AO29: 1760344 | AP29: 17437412 | AQ29: Roberto | AR29: Gutierrez Plazarte | AS29: NULL | AT29: NULL | AU29: Cancelled | AV29: Cancelled | AW29: 46023 | AX29: 46023 | AY29: 45946 | AZ29: 45946 | BA29: 46190 | BB29: 46023 | BC29: 46023 | BD29: 45946 | BE29: 46190 | BF29: 45934 | BG29: 45984
A30: 2026 | B30: 46204 | C30: 430403 | D30: 106.15 | E30: 8774308 | F30: 5167749839 | G30: SEP | H30: RR | I30: EN | J30: Dental | K30: 212059681 | L30: 1000712451 | M30: =VLOOKUP(L30,Selma!H$1:H$3913,1,FALSE) -> 1000712451 | N30: In Selma's report | O30: Enrollee | P30: Spouse | Q30: Active Re-enrollee | R30: 30857 | S30: Sukhdeep | T30: Bhatti | U30: 44.77 | V30: 89.54 | W30: 89.54 | X30: NULL | Y30: NULL | Z30: APTC_CSR | AA30: HIGH | AB30: 83502GA002000301 | AC30: 3631 | AD30: Best Life Superior Dental Plan | AE30: 83502 | AF30: BEST Life and Health Insurance Company | AG30: 41 | AH30: lokhandwalasana@gmail.com | AI30: 4043339846 | AJ30: 3 | AK30: NULL | AL30: 30040 | AM30: AGENT | AN30: 9436 | AO30: 9436 | AP30: 20457319 | AQ30: CHARITY | AR30: GILLESPIE | AS30: NULL | AT30: NULL | AU30: Terminated | AV30: Terminated | AW30: 46023 | AX30: 46142 | AY30: 46032 | AZ30: 46006 | BA30: 46186 | BB30: 46023 | BC30: 46142 | BD30: 46006 | BE30: 46186 | BF30: 46100 | BG30: 46139
A31: 2026 | B31: 46204 | C31: 467246 | D31: 123.35 | E31: 7559930 | F31: 5118844799 | G31: SEP | H31: ON | I31: EN | J31: Dental | K31: 211002985 | L31: 1000773598 | M31: =VLOOKUP(L31,Selma!H$1:H$3913,1,FALSE) -> #N/A | N31: Not in Selma's report | O31: Enrollee | P31: Spouse | Q31: New Consumer | R31: 29730 | S31: Meron | T31: Debela | U31: 25.77 | V31: 51.54 | W31: 51.54 | X31: NULL | Y31: NULL | Z31: APTC_CSR | AA31: LOW | AB31: 83502GA002000601 | AC31: 3632 | AD31: Best Life Essential Value Dental Plan | AE31: 83502 | AF31: BEST Life and Health Insurance Company | AG31: 44 | AH31: aketsela@hotmail.com | AI31: 4048496808 | AJ31: 3 | AK31: GWINNETT | AL31: 30084 | AM31: AGENT | AN31: 551610 | AO31: 551610 | AP31: 17028382 | AQ31: JORGO | AR31: LEMMA | AS31: NULL | AT31: NULL | AU31: Terminated | AV31: Terminated | AW31: 46023 | AX31: 46203 | AY31: 45946 | AZ31: 45946 | BA31: 46176 | BB31: 46023 | BC31: 46203 | BD31: 46003 | BE31: 46176 | BF31: 45999 | BG31: 46003
A32: 2026 | B32: 46204 | C32: 577475 | D32: 102.9 | E32: 7523282 | F32: 5114815792 | G32: SEP | H32: ON | I32: EN | J32: Dental | K32: 210667685 | L32: 1000956338 | M32: =VLOOKUP(L32,Selma!H$1:H$3913,1,FALSE) -> 1000956338 | N32: In Selma's report | O32: Enrollee | P32: Child | Q32: Active Re-enrollee | R32: 37319 | S32: Wynter | T32: Bayne | U32: 19.07 | V32: 78.88 | W32: 78.88 | X32: NULL | Y32: NULL | Z32: APTC_CSR | AA32: LOW | AB32: 83502GA002000801 | AC32: 3634 | AD32: Best Life Essential Basic Dental Plan | AE32: 83502 | AF32: BEST Life and Health Insurance Company | AG32: 23 | AH32: bayne2girls@gmail.com | AI32: 7705978010 | AJ32: 3 | AK32: GWINNETT | AL32: 30045 | AM32: AGENT | AN32: 1176094 | AO32: 1176094 | AP32: 18924885 | AQ32: Aslynn | AR32: Peacock | AS32: HealthSherpa | AT32: HealthSherpa | AU32: Enrolled | AV32: Enrolled | AW32: 46023 | AX32: 46387 | AY32: 45946 | AZ32: 45946 | BA32: 46020 | BB32: 46023 | BC32: 46387 | BD32: 45946 | BE32: 46020 | BF32: 45996 | BG32: 46002
A33: 2026 | B33: 46204 | C33: 577475 | D33: 102.9 | E33: 7523282 | F33: 5114815792 | G33: SEP | H33: ON | I33: EN | J33: Dental | K33: 210667685 | L33: 1000956326 | M33: =VLOOKUP(L33,Selma!H$1:H$3913,1,FALSE) -> 1000956326 | N33: In Selma's report | O33: Enrollee | P33: Self | Q33: Active Re-enrollee | R33: 27176 | S33: Kristopher | T33: Bayne | U33: 20.37 | V33: 78.88 | W33: 78.88 | X33: NULL | Y33: NULL | Z33: APTC_CSR | AA33: LOW | AB33: 83502GA002000801 | AC33: 3634 | AD33: Best Life Essential Basic Dental Plan | AE33: 83502 | AF33: BEST Life and Health Insurance Company | AG33: 51 | AH33: bayne2girls@gmail.com | AI33: 7705978010 | AJ33: 3 | AK33: GWINNETT | AL33: 30045 | AM33: AGENT | AN33: 1176094 | AO33: 1176094 | AP33: 18924885 | AQ33: Aslynn | AR33: Peacock | AS33: HealthSherpa | AT33: HealthSherpa | AU33: Enrolled | AV33: Enrolled | AW33: 46023 | AX33: 46387 | AY33: 45946 | AZ33: 45946 | BA33: 46020 | BB33: 46023 | BC33: 46387 | BD33: 45946 | BE33: 46020 | BF33: 45996 | BG33: 46002
A34: 2026 | B34: 46204 | C34: 577475 | D34: 102.9 | E34: 7523282 | F34: 5114815792 | G34: SEP | H34: ON | I34: EN | J34: Dental | K34: 210667685 | L34: 1000956323 | M34: =VLOOKUP(L34,Selma!H$1:H$3913,1,FALSE) -> 1000956323 | N34: In Selma's report | O34: Enrollee | P34: Child | Q34: Active Re-enrollee | R34: 38299 | S34: Mackenzie | T34: Bayne | U34: 19.07 | V34: 78.88 | W34: 78.88 | X34: NULL | Y34: NULL | Z34: APTC_CSR | AA34: LOW | AB34: 83502GA002000801 | AC34: 3634 | AD34: Best Life Essential Basic Dental Plan | AE34: 83502 | AF34: BEST Life and Health Insurance Company | AG34: 21 | AH34: bayne2girls@gmail.com | AI34: 7705978010 | AJ34: 3 | AK34: GWINNETT | AL34: 30045 | AM34: AGENT | AN34: 1176094 | AO34: 1176094 | AP34: 18924885 | AQ34: Aslynn | AR34: Peacock | AS34: HealthSherpa | AT34: HealthSherpa | AU34: Enrolled | AV34: Enrolled | AW34: 46023 | AX34: 46387 | AY34: 45946 | AZ34: 45946 | BA34: 46020 | BB34: 46023 | BC34: 46387 | BD34: 45946 | BE34: 46020 | BF34: 45996 | BG34: 46002
A35: 2026 | B35: 46204 | C35: 598880 | D35: 105.07 | E35: 9194141 | F35: 5127220391 | G35: SEP | H35: ON | I35: EN | J35: Dental | K35: 211603770 | L35: 1000992290 | M35: =VLOOKUP(L35,Selma!H$1:H$3913,1,FALSE) -> 1000992290 | N35: In Selma's report | O35: Enrollee | P35: Child | Q35: Active Re-enrollee | R35: 38106 | S35: Zacori | T35: Hurt | U35: 16.07 | V35: 33.24 | W35: 33.24 | X35: NULL | Y35: NULL | Z35: APTC_CSR | AA35: LOW | AB35: 83502GA002000801 | AC35: 3634 | AD35: Best Life Essential Basic Dental Plan | AE35: 83502 | AF35: BEST Life and Health Insurance Company | AG35: 21 | AH35: stephanie.hurt@ymail.com | AI35: 4042686997 | AJ35: 12 | AK35: Jones | AL35: 31032 | AM35: AGENT | AN35: 548849 | AO35: 548849 | AP35: 7658400 | AQ35: CHRISTINA FACAINE | AR35: BATTLE | AS35: HealthSherpa | AT35: HealthSherpa | AU35: Enrolled | AV35: Terminated | AW35: 46023 | AX35: 46387 | AY35: 46001 | AZ35: 45965 | BA35: 46161 | BB35: 46023 | BC35: 46173 | BD35: 45965 | BE35: 46161 | BF35: 46161 | BG35: 46161
A36: 2026 | B36: 46204 | C36: 598880 | D36: 105.07 | E36: 9194141 | F36: 5127220391 | G36: SEP | H36: ON | I36: EN | J36: Dental | K36: 211603770 | L36: 1000992291 | M36: =VLOOKUP(L36,Selma!H$1:H$3913,1,FALSE) -> 1000992291 | N36: In Selma's report | O36: Enrollee | P36: Child | Q36: Active Re-enrollee | R36: 39071 | S36: Zachary | T36: Hurt | U36: 16.07 | V36: 33.24 | W36: 33.24 | X36: NULL | Y36: NULL | Z36: APTC_CSR | AA36: LOW | AB36: 83502GA002000801 | AC36: 3634 | AD36: Best Life Essential Basic Dental Plan | AE36: 83502 | AF36: BEST Life and Health Insurance Company | AG36: 19 | AH36: stephanie.hurt@ymail.com | AI36: 4042686997 | AJ36: 12 | AK36: Jones | AL36: 31032 | AM36: AGENT | AN36: 548849 | AO36: 548849 | AP36: 7658400 | AQ36: CHRISTINA FACAINE | AR36: BATTLE | AS36: HealthSherpa | AT36: HealthSherpa | AU36: Enrolled | AV36: Enrolled | AW36: 46023 | AX36: 46387 | AY36: 46001 | AZ36: 45965 | BA36: 46161 | BB36: 46023 | BC36: 46387 | BD36: 45965 | BE36: 46161 | BF36: 46161 | BG36: 46161
A37: 2026 | B37: 46204 | C37: 625394 | D37: 100.81 | E37: 8751389 | F37: 5119263437 | G37: SEP | H37: ON | I37: EN | J37: Dental | K37: 211966421 | L37: 1001036214 | M37: =VLOOKUP(L37,Selma!H$1:H$3913,1,FALSE) -> 1001036214 | N37: In Selma's report | O37: Enrollee | P37: Child | Q37: Automatic Re-enrollee | R37: 40720 | S37: KHOI | T37: NGUYEN | U37: 27.65 | V37: 117.75 | W37: 117.75 | X37: NULL | Y37: NULL | Z37: APTC_CSR | AA37: LOW | AB37: 83502GA002000801 | AC37: 3634 | AD37: Best Life Essential Basic Dental Plan | AE37: 83502 | AF37: BEST Life and Health Insurance Company | AG37: 14 | AH37: nhattx3110888@uagins.org | AI37: 6262974622 | AJ37: 15 | AK37: DECATUR | AL37: 39817 | AM37: AGENT | AN37: 11052 | AO37: 11052 | AP37: 17142578 | AQ37: NGAN | AR37: JUNGBLUTH | AS37: HealthSherpa | AT37: HealthSherpa | AU37: Enrolled | AV37: Enrolled | AW37: 46023 | AX37: 46387 | AY37: 46019 | AZ37: 46003 | BA37: 46019 | BB37: 46023 | BC37: 46387 | BD37: 46003 | BE37: 46019 | BF37: 46097 | BG37: 46097
A38: 2026 | B38: 46204 | C38: 625394 | D38: 100.81 | E38: 8751389 | F38: 5119263437 | G38: SEP | H38: ON | I38: EN | J38: Dental | K38: 211966421 | L38: 1001036216 | M38: =VLOOKUP(L38,Selma!H$1:H$3913,1,FALSE) -> 1001036216 | N38: In Selma's report | O38: Enrollee | P38: Spouse | Q38: Automatic Re-enrollee | R38: 31389 | S38: OANH | T38: DANG | U38: 17.4 | V38: 117.75 | W38: 117.75 | X38: NULL | Y38: NULL | Z38: APTC_CSR | AA38: LOW | AB38: 83502GA002000801 | AC38: 3634 | AD38: Best Life Essential Basic Dental Plan | AE38: 83502 | AF38: BEST Life and Health Insurance Company | AG38: 40 | AH38: nhattx3110888@uagins.org | AI38: 6262974622 | AJ38: 15 | AK38: DECATUR | AL38: 39817 | AM38: AGENT | AN38: 11052 | AO38: 11052 | AP38: 17142578 | AQ38: NGAN | AR38: JUNGBLUTH | AS38: HealthSherpa | AT38: HealthSherpa | AU38: Enrolled | AV38: Enrolled | AW38: 46023 | AX38: 46387 | AY38: 46019 | AZ38: 46003 | BA38: 46019 | BB38: 46023 | BC38: 46387 | BD38: 46003 | BE38: 46019 | BF38: 46097 | BG38: 46097
A39: 2026 | B39: 46204 | C39: 625394 | D39: 100.81 | E39: 8751389 | F39: 5119263437 | G39: SEP | H39: ON | I39: EN | J39: Dental | K39: 211966421 | L39: 1001036215 | M39: =VLOOKUP(L39,Selma!H$1:H$3913,1,FALSE) -> 1001036215 | N39: In Selma's report | O39: Enrollee | P39: Child | Q39: Automatic Re-enrollee | R39: 42437 | S39: STEVEN | T39: NGUYEN | U39: 27.65 | V39: 117.75 | W39: 117.75 | X39: NULL | Y39: NULL | Z39: APTC_CSR | AA39: LOW | AB39: 83502GA002000801 | AC39: 3634 | AD39: Best Life Essential Basic Dental Plan | AE39: 83502 | AF39: BEST Life and Health Insurance Company | AG39: 9 | AH39: nhattx3110888@uagins.org | AI39: 6262974622 | AJ39: 15 | AK39: DECATUR | AL39: 39817 | AM39: AGENT | AN39: 11052 | AO39: 11052 | AP39: 17142578 | AQ39: NGAN | AR39: JUNGBLUTH | AS39: HealthSherpa | AT39: HealthSherpa | AU39: Enrolled | AV39: Enrolled | AW39: 46023 | AX39: 46387 | AY39: 46019 | AZ39: 46003 | BA39: 46019 | BB39: 46023 | BC39: 46387 | BD39: 46003 | BE39: 46019 | BF39: 46097 | BG39: 46097
... A49: 2026 | B49: 46204 | C49: 911633 | D49: 111.98 | E49: 6183470 | F49: 5148764469 | G49: OE | H49: CN | I49: EN | J49: Dental | K49: 210959356 | L49: 1001510407 | M49: =VLOOKUP(L49,Selma!H$1:H$3913,1,FALSE) -> 1001510407 | N49: In Selma's report | O49: Enrollee | P49: Child | Q49: Automatic Re-enrollee | R49: 39555 | S49: Aniyah | T49: Sims | U49: 33.34 | V49: 106.45 | W49: 106.45 | X49: NULL | Y49: NULL | Z49: APTC_CSR | AA49: LOW | AB49: 83502GA002000801 | AC49: 3634 | AD49: Best Life Essential Basic Dental Plan | AE49: 83502 | AF49: BEST Life and Health Insurance Company | AG49: 17 | AH49: aaron7918@gmail.com | AI49: 9174124470 | AJ49: 3 | AK49: DOUGLAS | AL49: 30135 | AM49: AGENT | AN49: 6168 | AO49: 6168 | AP49: 17128585 | AQ49: JUSTIN | AR49: FITZGERALD | AS49: NULL | AT49: NULL | AU49: Cancelled | AV49: Cancelled | AW49: 46023 | AX49: 46023 | AY49: 45946 | AZ49: 45946 | BA49: 46005 | BB49: 46023 | BC49: 46023 | BD49: 45946 | BE49: 46005 | BF49: 45934 | BG49: 46005
...

Sheet Sheet3
A3: Count of member ID | B3: Column Labels
A4: Row Labels | B4: 2025 | C4: 2026 | D4: Grand Total
A5: In Swathi's report | B5: 1199 | C5: 753 | D5: 1952
A6: Not in Swathi's report | B6: 1772 | C6: 188 | D6: 1960
A7: Grand Total | B7: 2971 | C7: 941 | D7: 3912

Sheet Selma
A1: HIOS ID | B1: Insurance Type | C1: Coveragge Year | D1: Folder Year | E1: Policy Id | F1: Enrollee Id | G1: Health Coverage Policy No | H1: member ID | I1: M ID from Swathi? | J1: M ID in Swathi's report - Status | K1: Issuer indiv identifier | L1: Exchngassigned enrollee id
A2: 83502 | B2: Dental | C2: 2025 | D2: 2025 | E2: 100058 | F2: 1000600684 | G2: 110586889 | H2: 1000600684 | I2: =VLOOKUP(H2,Swathi!L$1:L$1765,1,FALSE) -> 1000600684 | J2: In Swathi's report | K2: 110586889 | L2: NULL
A3: 83502 | B3: Dental | C3: 2025 | D3: 2025 | E3: 1001669 | F3: 1000554900 | G3: 108045704 | H3: 1000554900 | I3: =VLOOKUP(H3,Swathi!L$1:L$1765,1,FALSE) -> 1000554900 | J3: In Swathi's report | K3: 108045704 | L3: NULL
A4: 83502 | B4: Dental | C4: 2025 | D4: 2025 | E4: 1001674 | F4: 1001098323 | G4: 109802612 | H4: 1001098323 | I4: =VLOOKUP(H4,Swathi!L$1:L$1765,1,FALSE) -> #N/A | J4: Not in Swathi's report | K4: 109802612 | L4: NULL
A5: 83502 | B5: Dental | C5: 2025 | D5: 2025 | E5: 100310 | F5: 1001677413 | G5: 110520320 | H5: 1001677413 | I5: =VLOOKUP(H5,Swathi!L$1:L$1765,1,FALSE) -> 1001677413 | J5: In Swathi's report | K5: 110520320 | L5: NULL
A6: 83502 | B6: Dental | C6: 2025 | D6: 2025 | E6: 1003467 | F6: 1001053765 | G6: 110377060 | H6: 1001053765 | I6: =VLOOKUP(H6,Swathi!L$1:L$1765,1,FALSE) -> 1001053765 | J6: In Swathi's report | K6: 110377060 | L6: NULL
A7: 83502 | B7: Dental | C7: 2025 | D7: 2025 | E7: 100572 | F7: 1000467232 | G7: 110672656 | H7: 1000467232 | I7: =VLOOKUP(H7,Swathi!L$1:L$1765,1,FALSE) -> #N/A | J7: Not in Swathi's report | K7: 110672656 | L7: NULL
A8: 83502 | B8: Dental | C8: 2025 | D8: 2025 | E8: 1006308 | F8: 1000306554 | G8: 106285968 | H8: 1000306554 | I8: =VLOOKUP(H8,Swathi!L$1:L$1765,1,FALSE) -> 1000306554 | J8: In Swathi's report | K8: 106285968 | L8: NULL
A9: 83502 | B9: Dental | C9: 2025 | D9: 2025 | E9: 1006497 | F9: 1000917875 | G9: 110300788 | H9: 1000917875 | I9: =VLOOKUP(H9,Swathi!L$1:L$1765,1,FALSE) -> 1000917875 | J9: In Swathi's report | K9: 110300788 | L9: NULL
A10: 83502 | B10: Dental | C10: 2025 | D10: 2025 | E10: 1006700 | F10: 1001056900 | G10: NULL | H10: 1001056900 | I10: =VLOOKUP(H10,Swathi!L$1:L$1765,1,FALSE) -> 1001056900 | J10: In Swathi's report | K10: 53379832 | L10: NULL
A11: 83502 | B11: Dental | C11: 2025 | D11: 2025 | E11: 1008308 | F11: 1000975819 | G11: NULL | H11: 1000975819 | I11: =VLOOKUP(H11,Swathi!L$1:L$1765,1,FALSE) -> #N/A | J11: Not in Swathi's report | K11: 53379832 | L11: NULL
A12: 83502 | B12: Dental | C12: 2025 | D12: 2025 | E12: 10090369 | F12: 1001373500 | G12: NULL | H12: 1001373500 | I12: =VLOOKUP(H12,Swathi!L$1:L$1765,1,FALSE) -> #N/A | J12: Not in Swathi's report | K12: 53379832 | L12: NULL
A13: 83502 | B13: Dental | C13: 2025 | D13: 2025 | E13: 1009307 | F13: 1000666341 | G13: NULL | H13: 1000666341 | I13: =VLOOKUP(H13,Swathi!L$1:L$1765,1,FALSE) -> #N/A | J13: Not in Swathi's report | K13: 53379832 | L13: NULL
A14: 83502 | B14: Dental | C14: 2025 | D14: 2025 | E14: 1011230 | F14: 1001440431 | G14: NULL | H14: 1001440431 | I14: =VLOOKUP(H14,Swathi!L$1:L$1765,1,FALSE) -> #N/A | J14: Not in Swathi's report | K14: 53379832 | L14: NULL
A15: 83502 | B15: Dental | C15: 2025 | D15: 2025 | E15: 1013402 | F15: 1000140424 | G15: NULL | H15: 1000140424 | I15: =VLOOKUP(H15,Swathi!L$1:L$1765,1,FALSE) -> #N/A | J15: Not in Swathi's report | K15: 53379832 | L15: NULL
A16: 83502 | B16: Dental | C16: 2025 | D16: 2025 | E16: 1014254 | F16: 1001563044 | G16: NULL | H16: 1001563044 | I16: =VLOOKUP(H16,Swathi!L$1:L$1765,1,FALSE) -> #N/A | J16: Not in Swathi's report | K16: 53379832 | L16: NULL
A17: 83502 | B17: Dental | C17: 2025 | D17: 2025 | E17: 1019265 | F17: 1000416363 | G17: 107986004 | H17: 1000416363 | I17: =VLOOKUP(H17,Swathi!L$1:L$1765,1,FALSE) -> 1000416363 | J17: In Swathi's report | K17: 107986004 | L17: NULL
A18: 83502 | B18: Dental | C18: 2025 | D18: 2025 | E18: 10201347 | F18: 1001086740 | G18: NULL | H18: 1001086740 | I18: =VLOOKUP(H18,Swathi!L$1:L$1765,1,FALSE) -> #N/A | J18: Not in Swathi's report | K18: 53379832 | L18: NULL
A19: 83502 | B19: Dental | C19: 2025 | D19: 2025 | E19: 1022256 | F19: 1001000383 | G19: NULL | H19: 1001000383 | I19: =VLOOKUP(H19,Swathi!L$1:L$1765,1,FALSE) -> #N/A | J19: Not in Swathi's report | K19: 53379832 | L19: NULL
A20: 83502 | B20: Dental | C20: 2025 | D20: 2025 | E20: 1024335 | F20: 1000909226 | G20: 105009068 | H20: 1000909226 | I20: =VLOOKUP(H20,Swathi!L$1:L$1765,1,FALSE) -> 1000909226 | J20: In Swathi's report | K20: 105009068 | L20: NULL
A21: 83502 | B21: Dental | C21: 2025 | D21: 2025 | E21: 1025486 | F21: 1000872961 | G21: 109668296 | H21: 1000872961 | I21: =VLOOKUP(H21,Swathi!L$1:L$1765,1,FALSE) -> #N/A | J21: Not in Swathi's report | K21: 109668296 | L21: NULL
A22: 83502 | B22: Dental | C22: 2025 | D22: 2025 | E22: 1025486 | F22: 1000872961 | G22: NULL | H22: 1000872961 | I22: =VLOOKUP(H22,Swathi!L$1:L$1765,1,FALSE) -> #N/A | J22: Not in Swathi's report | K22: 53379832 | L22: NULL
A23: 83502 | B23: Dental | C23: 2025 | D23: 2025 | E23: 1027446 | F23: 1000643099 | G23: NULL | H23: 1000643099 | I23: =VLOOKUP(H23,Swathi!L$1:L$1765,1,FALSE) -> #N/A | J23: Not in Swathi's report | K23: 53379832 | L23: NULL
A24: 83502 | B24: Dental | C24: 2025 | D24: 2025 | E24: 1027668 | F24: 1001261233 | G24: NULL | H24: 1001261233 | I24: =VLOOKUP(H24,Swathi!L$1:L$1765,1,FALSE) -> #N/A | J24: Not in Swathi's report | K24: 53379832 | L24: NULL
A25: 83502 | B25: Dental | C25: 2025 | D25: 2025 | E25: 1031308 | F25: 1000171756 | G25: 110769429 | H25: 1000171756 | I25: =VLOOKUP(H25,Swathi!L$1:L$1765,1,FALSE) -> 1000171756 | J25: In Swathi's report | K25: 110769429 | L25: NULL
A26: 83502 | B26: Dental | C26: 2025 | D26: 2025 | E26: 103256 | F26: 1001643645 | G26: 110307900 | H26: 1001643645 | I26: =VLOOKUP(H26,Swathi!L$1:L$1765,1,FALSE) -> 1001643645 | J26: In Swathi's report | K26: 110307900 | L26: NULL
A27: 83502 | B27: Dental | C27: 2025 | D27: 2025 | E27: 103256 | F27: 1001643655 | G27: 110307900 | H27: 1001643655 | I27: =VLOOKUP(H27,Swathi!L$1:L$1765,1,FALSE) -> 1001643655 | J27: In Swathi's report | K27: 445936 | L27: NULL
A28: 83502 | B28: Dental | C28: 2025 | D28: 2025 | E28: 1033306 | F28: 1001376779 | G28: NULL | H28: 1001376779 | I28: =VLOOKUP(H28,Swathi!L$1:L$1765,1,FALSE) -> 1001376779 | J28: In Swathi's report | K28: 53379832 | L28: NULL
A29: 83502 | B29: Dental | C29: 2025 | D29: 2025 | E29: 1033306 | F29: 1001376779 | G29: NULL | H29: 1001376779 | I29: =VLOOKUP(H29,Swathi!L$1:L$1765,1,FALSE) -> 1001376779 | J29: In Swathi's report | K29: 53379832 | L29: NULL
A30: 83502 | B30: Dental | C30: 2025 | D30: 2025 | E30: 1033306 | F30: 1001376779 | G30: NULL | H30: 1001376779 | I30: =VLOOKUP(H30,Swathi!L$1:L$1765,1,FALSE) -> 1001376779 | J30: In Swathi's report | K30: 53379832 | L30: NULL
A31: 83502 | B31: Dental | C31: 2025 | D31: 2025 | E31: 1033391 | F31: 1000554435 | G31: 110497412 | H31: 1000554435 | I31: =VLOOKUP(H31,Swathi!L$1:L$1765,1,FALSE) -> 1000554435 | J31: In Swathi's report | K31: 110497412 | L31: NULL
A32: 83502 | B32: Dental | C32: 2025 | D32: 2025 | E32: 103357 | F32: 1000577674 | G32: NULL | H32: 1000577674 | I32: =VLOOKUP(H32,Swathi!L$1:L$1765,1,FALSE) -> #N/A | J32: Not in Swathi's report | K32: 53379832 | L32: NULL
A33: 83502 | B33: Dental | C33: 2025 | D33: 2025 | E33: 103371 | F33: 1000609907 | G33: NULL | H33: 1000609907 | I33: =VLOOKUP(H33,Swathi!L$1:L$1765,1,FALSE) -> #N/A | J33: Not in Swathi's report | K33: 53379832 | L33: NULL
A34: 83502 | B34: Dental | C34: 2025 | D34: 2025 | E34: 10339338 | F34: 1001725424 | G34: 110893278 | H34: 1001725424 | I34: =VLOOKUP(H34,Swathi!L$1:L$1765,1,FALSE) -> 1001725424 | J34: In Swathi's report | K34: 110893278 | L34: NULL
A35: 83502 | B35: Dental | C35: 2025 | D35: 2025 | E35: 1036339 | F35: 1000725287 | G35: NULL | H35: 1000725287 | I35: =VLOOKUP(H35,Swathi!L$1:L$1765,1,FALSE) -> #N/A | J35: Not in Swathi's report | K35: 53379832 | L35: NULL
A36: 83502 | B36: Dental | C36: 2025 | D36: 2025 | E36: 1039719 | F36: 1000426411 | G36: 110260831 | H36: 1000426411 | I36: =VLOOKUP(H36,Swathi!L$1:L$1765,1,FALSE) -> 1000426411 | J36: In Swathi's report | K36: 110260831 | L36: NULL
A37: 83502 | B37: Dental | C37: 2025 | D37: 2025 | E37: 1039719 | F37: 1000426412 | G37: 110260831 | H37: 1000426412 | I37: =VLOOKUP(H37,Swathi!L$1:L$1765,1,FALSE) -> 1000426412 | J37: In Swathi's report | K37: 443990 | L37: NULL
A38: 83502 | B38: Dental | C38: 2025 | D38: 2025 | E38: 1039788 | F38: 1000804700 | G38: NULL | H38: 1000804700 | I38: =VLOOKUP(H38,Swathi!L$1:L$1765,1,FALSE) -> #N/A | J38: Not in Swathi's report | K38: 53379832 | L38: NULL
A39: 83502 | B39: Dental | C39: 2025 | D39: 2025 | E39: 1041310 | F39: 1000765192 | G39: NULL | H39: 1000765192 | I39: =VLOOKUP(H39,Swathi!L$1:L$1765,1,FALSE) -> #N/A | J39: Not in Swathi's report | K39: 53379832 | L39: NULL
A40: 83502 | B40: Dental | C40: 2025 | D40: 2025 | E40: 1046279 | F40: 1000388290 | G40: NULL | H40: 1000388290 | I40: =VLOOKUP(H40,Swathi!L$1:L$1765,1,FALSE) -> #N/A | J40: Not in Swathi's report | K40: 53379832 | L40: NULL
...
